<?xml version="1.0" encoding="utf-8"?>
<!-- This URDF was automatically created by SolidWorks to URDF Exporter! Originally created by Stephen Brawner (brawner@gmail.com) 
     Commit Version: 1.6.0-4-g7f85cfe  Build Version: 1.6.7995.38578
     For more information, please see http://wiki.ros.org/sw_urdf_exporter -->
<robot
  name="xytronY">
  <link
    name="base_link">
    <inertial>
      <origin
        xyz="-0.023141 0.0071464 -2.5905E-08"
        rpy="0 0 0" />
      <mass
        value="11.505" />
      <inertia
        ixx="0.057941"
        ixy="-0.0048362"
        ixz="-2.5661E-08"
        iyy="0.17549"
        iyz="-6.1659E-08"
        izz="0.1801" />
    </inertial>
    <visual>
      <origin
        xyz="0 0 0"
        rpy="0 0 0" />
      <geometry>
        <mesh
          filename="package://xytronY/meshes/base_link.STL" />
      </geometry>
      <material
        name="">
        <color
          rgba="192 192 192 1" />
      </material>
    </visual>
    <collision>
      <origin
        xyz="0 0 0"
        rpy="0 0 0" />
      <geometry>
        <mesh
          filename="package://xytronY/meshes/base_link.STL" />
      </geometry>
    </collision>
  </link>
  <link
    name="F_R_link">
    <inertial>
      <origin
        xyz="0 0 0.043695"
        rpy="0 0 0" />
      <mass
        value="0.39886" />
      <inertia
        ixx="0.000348"
        ixy="0"
        ixz="-1.8117E-21"
        iyy="0.000348"
        iyz="5.4102E-22"
        izz="0.00048566" />
    </inertial>
    <visual>
      <origin
        xyz="0 0 0"
        rpy="0 0 0" />
      <geometry>
        <mesh
          filename="package://xytronY/meshes/F_R_link.STL" />
      </geometry>
      <material
        name="">
        <color
          rgba="1 1 1 1" />
      </material>
    </visual>
    <collision>
      <origin
        xyz="0 0 0"
        rpy="0 0 0" />
      <geometry>
        <mesh
          filename="package://xytronY/meshes/F_R_link.STL" />
      </geometry>
    </collision>
  </link>
  <joint
    name="F_R_joint"
    type="continuous">
    <origin
      xyz="0.16081 -0.023 -0.0621"
      rpy="1.5708 -0.68589 0" />
    <parent
      link="base_link" />
    <child
      link="F_R_link" />
    <axis
      xyz="0 0 1" />
  </joint>
  <link
    name="F_L_link">
    <inertial>
      <origin
        xyz="4.1633E-17 4.1633E-17 0.039695"
        rpy="0 0 0" />
      <mass
        value="0.39886" />
      <inertia
        ixx="0.000348"
        ixy="2.7105E-20"
        ixz="-6.9279E-21"
        iyy="0.000348"
        iyz="6.0116E-21"
        izz="0.00048566" />
    </inertial>
    <visual>
      <origin
        xyz="0 0 0"
        rpy="0 0 0" />
      <geometry>
        <mesh
          filename="package://xytronY/meshes/F_L_link.STL" />
      </geometry>
      <material
        name="">
        <color
          rgba="1 1 1 1" />
      </material>
    </visual>
    <collision>
      <origin
        xyz="0 0 0"
        rpy="0 0 0" />
      <geometry>
        <mesh
          filename="package://xytronY/meshes/F_L_link.STL" />
      </geometry>
    </collision>
  </link>
  <joint
    name="F_L_joint"
    type="continuous">
    <origin
      xyz="0.16081 0.027 -0.0621"
      rpy="1.5708 0.39309 -3.1416" />
    <parent
      link="base_link" />
    <child
      link="F_L_link" />
    <axis
      xyz="0 0 1" />
  </joint>
  <link
    name="B_R_link">
    <inertial>
      <origin
        xyz="-2.0817E-17 -2.7756E-17 0.043695"
        rpy="0 0 0" />
      <mass
        value="0.39886" />
      <inertia
        ixx="0.000348"
        ixy="-2.7105E-20"
        ixz="-5.7064E-21"
        iyy="0.000348"
        iyz="9.0481E-21"
        izz="0.00048566" />
    </inertial>
    <visual>
      <origin
        xyz="0 0 0"
        rpy="0 0 0" />
      <geometry>
        <mesh
          filename="package://xytronY/meshes/B_R_link.STL" />
      </geometry>
      <material
        name="">
        <color
          rgba="1 1 1 1" />
      </material>
    </visual>
    <collision>
      <origin
        xyz="0 0 0"
        rpy="0 0 0" />
      <geometry>
        <mesh
          filename="package://xytronY/meshes/B_R_link.STL" />
      </geometry>
    </collision>
  </link>
  <joint
    name="B_R_joint"
    type="continuous">
    <origin
      xyz="-0.17419 -0.023 -0.0621"
      rpy="1.5708 0.9325 0" />
    <parent
      link="base_link" />
    <child
      link="B_R_link" />
    <axis
      xyz="0 0 1" />
  </joint>
  <link
    name="B_L_link">
    <inertial>
      <origin
        xyz="-5.5511E-17 -2.7756E-17 0.039695"
        rpy="0 0 0" />
      <mass
        value="0.39886" />
      <inertia
        ixx="0.000348"
        ixy="0"
        ixz="-6.9279E-21"
        iyy="0.000348"
        iyz="6.0116E-21"
        izz="0.00048566" />
    </inertial>
    <visual>
      <origin
        xyz="0 0 0"
        rpy="0 0 0" />
      <geometry>
        <mesh
          filename="package://xytronY/meshes/B_L_link.STL" />
      </geometry>
      <material
        name="">
        <color
          rgba="1 1 1 1" />
      </material>
    </visual>
    <collision>
      <origin
        xyz="0 0 0"
        rpy="0 0 0" />
      <geometry>
        <mesh
          filename="package://xytronY/meshes/B_L_link.STL" />
      </geometry>
    </collision>
  </link>
  <joint
    name="B_L_joint"
    type="continuous">
    <origin
      xyz="-0.17419 0.027 -0.0621"
      rpy="1.5708 0.39309 -3.1416" />
    <parent
      link="base_link" />
    <child
      link="B_L_link" />
    <axis
      xyz="0 0 1" />
  </joint>
  <link
    name="Lidar_link">
    <inertial>
      <origin
        xyz="-2.7756E-17 -1.3976E-17 0.0015995"
        rpy="0 0 0" />
      <mass
        value="0.076576" />
      <inertia
        ixx="2.1671E-05"
        ixy="-5.6231E-54"
        ixz="9.1835E-38"
        iyy="2.1671E-05"
        iyz="-1.3832E-22"
        izz="2.393E-05" />
    </inertial>
    <visual>
      <origin
        xyz="0 0 0"
        rpy="0 0 0" />
      <geometry>
        <mesh
          filename="package://xytronY/meshes/Lidar_link.STL" />
      </geometry>
      <material
        name="">
        <color
          rgba="0 1 0 1" />
      </material>
    </visual>
    <collision>
      <origin
        xyz="0 0 0"
        rpy="0 0 0" />
      <geometry>
        <mesh
          filename="package://xytronY/meshes/Lidar_link.STL" />
      </geometry>
    </collision>
  </link>
  <joint
    name="Lidar_joint"
    type="continuous">
    <origin
      xyz="0.19412 0 0"
      rpy="3.1416 0 0" />
    <parent
      link="base_link" />
    <child
      link="Lidar_link" />
    <axis
      xyz="0 0 1" />
  </joint>
  <link
    name="Ulteasonic_R_link">
    <inertial>
      <origin
        xyz="-0.00026757 1.7347E-18 0.0067753"
        rpy="0 0 0" />
      <mass
        value="0.0079276" />
      <inertia
        ixx="3.6324E-07"
        ixy="-9.8319E-24"
        ixz="5.7795E-09"
        iyy="1.5422E-06"
        iyz="9.4032E-23"
        izz="1.5263E-06" />
    </inertial>
    <visual>
      <origin
        xyz="0 0 0"
        rpy="0 0 0" />
      <geometry>
        <mesh
          filename="package://xytronY/meshes/Ulteasonic_R_link.STL" />
      </geometry>
      <material
        name="">
        <color
          rgba="0 0 1 1" />
      </material>
    </visual>
    <collision>
      <origin
        xyz="0 0 0"
        rpy="0 0 0" />
      <geometry>
        <mesh
          filename="package://xytronY/meshes/Ulteasonic_R_link.STL" />
      </geometry>
    </collision>
  </link>
  <joint
    name="Ulteasonic_R_joint"
    type="fixed">
    <origin
      xyz="0.010615 -0.0905 -0.0050995"
      rpy="1.5708 0 0" />
    <parent
      link="base_link" />
    <child
      link="Ulteasonic_R_link" />
    <axis
      xyz="0 0 0" />
  </joint>
  <link
    name="Ulteasonic_L_link">
    <inertial>
      <origin
        xyz="-0.00026757 1.7347E-18 0.0067753"
        rpy="0 0 0" />
      <mass
        value="0.0079276" />
      <inertia
        ixx="3.6324E-07"
        ixy="2.1393E-23"
        ixz="5.7795E-09"
        iyy="1.5422E-06"
        iyz="8.3254E-23"
        izz="1.5263E-06" />
    </inertial>
    <visual>
      <origin
        xyz="0 0 0"
        rpy="0 0 0" />
      <geometry>
        <mesh
          filename="package://xytronY/meshes/Ulteasonic_L_link.STL" />
      </geometry>
      <material
        name="">
        <color
          rgba="0 0 1 1" />
      </material>
    </visual>
    <collision>
      <origin
        xyz="0 0 0"
        rpy="0 0 0" />
      <geometry>
        <mesh
          filename="package://xytronY/meshes/Ulteasonic_L_link.STL" />
      </geometry>
    </collision>
  </link>
  <joint
    name="Ulteasonic_L_joint"
    type="fixed">
    <origin
      xyz="0.010615 0.0905 -0.0050995"
      rpy="1.5708 0 3.1416" />
    <parent
      link="base_link" />
    <child
      link="Ulteasonic_L_link" />
    <axis
      xyz="0 0 0" />
  </joint>
  <link
    name="Ulteasonic_B_R_link">
    <inertial>
      <origin
        xyz="-0.00026757 5.2042E-18 0.0067753"
        rpy="0 0 0" />
      <mass
        value="0.0079276" />
      <inertia
        ixx="3.6324E-07"
        ixy="3.251E-22"
        ixz="5.7795E-09"
        iyy="1.5422E-06"
        iyz="2.1071E-22"
        izz="1.5263E-06" />
    </inertial>
    <visual>
      <origin
        xyz="0 0 0"
        rpy="0 0 0" />
      <geometry>
        <mesh
          filename="package://xytronY/meshes/Ulteasonic_B_R_link.STL" />
      </geometry>
      <material
        name="">
        <color
          rgba="0 0 1 1" />
      </material>
    </visual>
    <collision>
      <origin
        xyz="0 0 0"
        rpy="0 0 0" />
      <geometry>
        <mesh
          filename="package://xytronY/meshes/Ulteasonic_B_R_link.STL" />
      </geometry>
    </collision>
  </link>
  <joint
    name="Ulteasonic_B_R_joint"
    type="fixed">
    <origin
      xyz="-0.27028 -0.062687 -0.0050995"
      rpy="1.5708 0 -0.95993" />
    <parent
      link="base_link" />
    <child
      link="Ulteasonic_B_R_link" />
    <axis
      xyz="0 0 0" />
  </joint>
  <link
    name="Ulteasonic_B_L_link">
    <inertial>
      <origin
        xyz="-0.00026757 8.6736E-19 0.0067753"
        rpy="0 0 0" />
      <mass
        value="0.0079276" />
      <inertia
        ixx="3.6324E-07"
        ixy="-3.1438E-22"
        ixz="5.7795E-09"
        iyy="1.5422E-06"
        iyz="1.025E-22"
        izz="1.5263E-06" />
    </inertial>
    <visual>
      <origin
        xyz="0 0 0"
        rpy="0 0 0" />
      <geometry>
        <mesh
          filename="package://xytronY/meshes/Ulteasonic_B_L_link.STL" />
      </geometry>
      <material
        name="">
        <color
          rgba="0 0 1 1" />
      </material>
    </visual>
    <collision>
      <origin
        xyz="0 0 0"
        rpy="0 0 0" />
      <geometry>
        <mesh
          filename="package://xytronY/meshes/Ulteasonic_B_L_link.STL" />
      </geometry>
    </collision>
  </link>
  <joint
    name="Ulteasonic_B_L_joint"
    type="fixed">
    <origin
      xyz="-0.27028 0.062687 -0.0050995"
      rpy="1.5708 0 -2.1817" />
    <parent
      link="base_link" />
    <child
      link="Ulteasonic_B_L_link" />
    <axis
      xyz="0 0 0" />
  </joint>
  <link
    name="Ulteasonic_B_M_link">
    <inertial>
      <origin
        xyz="-0.00026757 -1.7347E-18 -0.0067753"
        rpy="0 0 0" />
      <mass
        value="0.0079276" />
      <inertia
        ixx="3.6324E-07"
        ixy="1.3884E-23"
        ixz="-5.7795E-09"
        iyy="1.5422E-06"
        iyz="9.7284E-23"
        izz="1.5263E-06" />
    </inertial>
    <visual>
      <origin
        xyz="0 0 0"
        rpy="0 0 0" />
      <geometry>
        <mesh
          filename="package://xytronY/meshes/Ulteasonic_B_M_link.STL" />
      </geometry>
      <material
        name="">
        <color
          rgba="0 0 1 1" />
      </material>
    </visual>
    <collision>
      <origin
        xyz="0 0 0"
        rpy="0 0 0" />
      <geometry>
        <mesh
          filename="package://xytronY/meshes/Ulteasonic_B_M_link.STL" />
      </geometry>
    </collision>
  </link>
  <joint
    name="Ulteasonic_B_M_joint"
    type="fixed">
    <origin
      xyz="-0.28988 0 -0.0050995"
      rpy="-1.5708 0 -1.5708" />
    <parent
      link="base_link" />
    <child
      link="Ulteasonic_B_M_link" />
    <axis
      xyz="0 0 0" />
  </joint>
  <link
    name="cam_link">
    <inertial>
      <origin
        xyz="0.016638 0.0004604 6.5384E-22"
        rpy="0 0 0" />
      <mass
        value="0.0037561" />
      <inertia
        ixx="2.1559E-07"
        ixy="5.3104E-09"
        ixz="-6.8025E-25"
        iyy="1.6276E-07"
        iyz="8.7938E-24"
        izz="1.3133E-07" />
    </inertial>
    <visual>
      <origin
        xyz="0 0 0"
        rpy="0 0 0" />
      <geometry>
        <mesh
          filename="package://xytronY/meshes/cam_link.STL" />
      </geometry>
      <material
        name="">
        <color
          rgba="1 0 0 1" />
      </material>
    </visual>
    <collision>
      <origin
        xyz="0 0 0"
        rpy="0 0 0" />
      <geometry>
        <mesh
          filename="package://xytronY/meshes/cam_link.STL" />
      </geometry>
    </collision>
  </link>
  <joint
    name="cam_joint"
    type="fixed">
    <origin
      xyz="0.14716 0 0.07398"
      rpy="1.5708 0 0" />
    <parent
      link="base_link" />
    <child
      link="cam_link" />
    <axis
      xyz="0 0 0" />
  </joint>
</robot>